Sat Mar 25 20:38:14 CET 2023 Thread[#67,Thread-5,5,main] Cleanup action starting
java.sql.SQLException: Database 'db' not found.
	at org.apache.derby.impl.jdbc.SQLExceptionFactory.getSQLException(SQLExceptionFactory.java:115)
	at org.apache.derby.impl.jdbc.SQLExceptionFactory.getSQLException(SQLExceptionFactory.java:141)
	at org.apache.derby.impl.jdbc.Util.generateCsSQLException(Util.java:225)
	at org.apache.derby.impl.jdbc.Util.generateCsSQLException(Util.java:220)
	at org.apache.derby.impl.jdbc.EmbedConnection.newSQLException(EmbedConnection.java:3208)
	at org.apache.derby.impl.jdbc.EmbedConnection.handleDBNotFound(EmbedConnection.java:767)
	at org.apache.derby.impl.jdbc.EmbedConnection.<init>(EmbedConnection.java:437)
	at org.apache.derby.iapi.jdbc.InternalDriver.getNewEmbedConnection(InternalDriver.java:630)
	at org.apache.derby.iapi.jdbc.InternalDriver$LoginCallable.call(InternalDriver.java:400)
	at org.apache.derby.iapi.jdbc.InternalDriver$LoginCallable.call(InternalDriver.java:376)
	at java.base/java.util.concurrent.FutureTask.run(FutureTask.java:317)
	at java.base/java.util.concurrent.ThreadPoolExecutor.runWorker(ThreadPoolExecutor.java:1144)
	at java.base/java.util.concurrent.ThreadPoolExecutor$Worker.run(ThreadPoolExecutor.java:642)
	at java.base/java.lang.Thread.run(Thread.java:1623)
Caused by: ERROR XJ004: Database 'db' not found.
	at org.apache.derby.shared.common.error.StandardException.newException(StandardException.java:299)
	at org.apache.derby.impl.jdbc.SQLExceptionFactory.wrapArgsForTransportAcrossDRDA(SQLExceptionFactory.java:170)
	at org.apache.derby.impl.jdbc.SQLExceptionFactory.getSQLException(SQLExceptionFactory.java:75)
	... 13 more
============= begin nested exception, level (1) ===========
ERROR XJ004: Database 'db' not found.
	at org.apache.derby.shared.common.error.StandardException.newException(StandardException.java:299)
	at org.apache.derby.impl.jdbc.SQLExceptionFactory.wrapArgsForTransportAcrossDRDA(SQLExceptionFactory.java:170)
	at org.apache.derby.impl.jdbc.SQLExceptionFactory.getSQLException(SQLExceptionFactory.java:75)
	at org.apache.derby.impl.jdbc.SQLExceptionFactory.getSQLException(SQLExceptionFactory.java:141)
	at org.apache.derby.impl.jdbc.Util.generateCsSQLException(Util.java:225)
	at org.apache.derby.impl.jdbc.Util.generateCsSQLException(Util.java:220)
	at org.apache.derby.impl.jdbc.EmbedConnection.newSQLException(EmbedConnection.java:3208)
	at org.apache.derby.impl.jdbc.EmbedConnection.handleDBNotFound(EmbedConnection.java:767)
	at org.apache.derby.impl.jdbc.EmbedConnection.<init>(EmbedConnection.java:437)
	at org.apache.derby.iapi.jdbc.InternalDriver.getNewEmbedConnection(InternalDriver.java:630)
	at org.apache.derby.iapi.jdbc.InternalDriver$LoginCallable.call(InternalDriver.java:400)
	at org.apache.derby.iapi.jdbc.InternalDriver$LoginCallable.call(InternalDriver.java:376)
	at java.base/java.util.concurrent.FutureTask.run(FutureTask.java:317)
	at java.base/java.util.concurrent.ThreadPoolExecutor.runWorker(ThreadPoolExecutor.java:1144)
	at java.base/java.util.concurrent.ThreadPoolExecutor$Worker.run(ThreadPoolExecutor.java:642)
	at java.base/java.lang.Thread.run(Thread.java:1623)
============= end nested exception, level (1) ===========
Cleanup action completed
Sat Mar 25 20:38:43 CET 2023 Thread[#92,Thread-9,5,main] Cleanup action starting
java.sql.SQLException: Database 'db' not found.
	at org.apache.derby.impl.jdbc.SQLExceptionFactory.getSQLException(SQLExceptionFactory.java:115)
	at org.apache.derby.impl.jdbc.SQLExceptionFactory.getSQLException(SQLExceptionFactory.java:141)
	at org.apache.derby.impl.jdbc.Util.generateCsSQLException(Util.java:225)
	at org.apache.derby.impl.jdbc.Util.generateCsSQLException(Util.java:220)
	at org.apache.derby.impl.jdbc.EmbedConnection.newSQLException(EmbedConnection.java:3208)
	at org.apache.derby.impl.jdbc.EmbedConnection.handleDBNotFound(EmbedConnection.java:767)
	at org.apache.derby.impl.jdbc.EmbedConnection.<init>(EmbedConnection.java:437)
	at org.apache.derby.iapi.jdbc.InternalDriver.getNewEmbedConnection(InternalDriver.java:630)
	at org.apache.derby.iapi.jdbc.InternalDriver$LoginCallable.call(InternalDriver.java:400)
	at org.apache.derby.iapi.jdbc.InternalDriver$LoginCallable.call(InternalDriver.java:376)
	at java.base/java.util.concurrent.FutureTask.run(FutureTask.java:317)
	at java.base/java.util.concurrent.ThreadPoolExecutor.runWorker(ThreadPoolExecutor.java:1144)
	at java.base/java.util.concurrent.ThreadPoolExecutor$Worker.run(ThreadPoolExecutor.java:642)
	at java.base/java.lang.Thread.run(Thread.java:1623)
Caused by: ERROR XJ004: Database 'db' not found.
	at org.apache.derby.shared.common.error.StandardException.newException(StandardException.java:299)
	at org.apache.derby.impl.jdbc.SQLExceptionFactory.wrapArgsForTransportAcrossDRDA(SQLExceptionFactory.java:170)
	at org.apache.derby.impl.jdbc.SQLExceptionFactory.getSQLException(SQLExceptionFactory.java:75)
	... 13 more
============= begin nested exception, level (1) ===========
ERROR XJ004: Database 'db' not found.
	at org.apache.derby.shared.common.error.StandardException.newException(StandardException.java:299)
	at org.apache.derby.impl.jdbc.SQLExceptionFactory.wrapArgsForTransportAcrossDRDA(SQLExceptionFactory.java:170)
	at org.apache.derby.impl.jdbc.SQLExceptionFactory.getSQLException(SQLExceptionFactory.java:75)
	at org.apache.derby.impl.jdbc.SQLExceptionFactory.getSQLException(SQLExceptionFactory.java:141)
	at org.apache.derby.impl.jdbc.Util.generateCsSQLException(Util.java:225)
	at org.apache.derby.impl.jdbc.Util.generateCsSQLException(Util.java:220)
	at org.apache.derby.impl.jdbc.EmbedConnection.newSQLException(EmbedConnection.java:3208)
	at org.apache.derby.impl.jdbc.EmbedConnection.handleDBNotFound(EmbedConnection.java:767)
	at org.apache.derby.impl.jdbc.EmbedConnection.<init>(EmbedConnection.java:437)
	at org.apache.derby.iapi.jdbc.InternalDriver.getNewEmbedConnection(InternalDriver.java:630)
	at org.apache.derby.iapi.jdbc.InternalDriver$LoginCallable.call(InternalDriver.java:400)
	at org.apache.derby.iapi.jdbc.InternalDriver$LoginCallable.call(InternalDriver.java:376)
	at java.base/java.util.concurrent.FutureTask.run(FutureTask.java:317)
	at java.base/java.util.concurrent.ThreadPoolExecutor.runWorker(ThreadPoolExecutor.java:1144)
	at java.base/java.util.concurrent.ThreadPoolExecutor$Worker.run(ThreadPoolExecutor.java:642)
	at java.base/java.lang.Thread.run(Thread.java:1623)
============= end nested exception, level (1) ===========
Cleanup action completed
